<?xml version="1.0" ?>
<sdf version='1.6'>
  <world name='sim_world'>
    <model name='clifford'>
      <link name='body'>
        <pose frame=''>0 0 0 0 -0 0</pose>
        <inertial>
          <pose frame=''>0 -0 0 0 -0 0</pose>
          <mass>1.20456</mass>
          <inertia>
		  <ixx>0</ixx> <ixy>0</ixy> <ixz>0</ixz>
		  <iyy>0</iyy> <iyz>0</iyz> <izz>0</izz>
          </inertia>
        </inertial>
        <visual name='body_visual'>
          <pose frame=''>0 0 0 0 -0 0</pose>
          <geometry>
            <mesh>
              <scale>1 1 1</scale>
              <uri>model://meshes/body.STL</uri>
            </mesh>
          </geometry>
        </visual>
        <collision name='body_visual'>
          <pose frame=''>0 0 0 0 -0 0</pose>
          <geometry>
            <mesh>
              <scale>1 1 1</scale>
              <uri>model://meshes/body.STL</uri>
            </mesh>
          </geometry>
        </collision>
      </link>
      <link name='bro'>
        <pose frame=''>-0.101 -0.0615 -0.024 1.28235 0.269455 -3.09986</pose>
        <inertial>
          <pose frame=''>0.115 -0 -0 0 -0 0</pose>
          <mass>0.0117925</mass>
          <inertia>
		  <ixx>0</ixx> <ixy>0</ixy> <ixz>0</ixz>
		  <iyy>0</iyy> <iyz>0</iyz> <izz>0</izz>
          </inertia>
        </inertial>
        <visual name='bro_visual'>
          <pose frame=''>0 0 0 0 -0 0</pose>
          <geometry>
            <mesh>
              <scale>1 1 1</scale>
              <uri>model://meshes/linkageOut.STL</uri>
            </mesh>
          </geometry>
        </visual>
      </link>
      <link name='backAxle'>
        <pose frame=''>-0.322508 -0.07075 -0.085227 0.267288 -0 1.5708</pose>
        <inertial>
          <pose frame=''>0.07075 0.019868 0.013586 0 -0 0</pose>
          <mass>0.0969889</mass>
          <inertia>
		  <ixx>0</ixx> <ixy>0</ixy> <ixz>0</ixz>
		  <iyy>0</iyy> <iyz>0</iyz> <izz>0</izz>
          </inertia>
        </inertial>
        <visual name='backAxle_visual'>
          <pose frame=''>0 0 0 0 -0 0</pose>
          <geometry>
            <mesh>
              <scale>1 1 1</scale>
              <uri>model://meshes/axleRear.STL</uri>
            </mesh>
          </geometry>
        </visual>
        <collision name='backAxle_collision'>
          <pose frame=''>0 0 0 0 -0 0</pose>
          <geometry>
            <mesh>
              <scale>1 1 1</scale>
              <uri>model://meshes/axleRear.STL</uri>
            </mesh>
          </geometry>
        </collision>
      </link>
      <link name='bli'>
        <pose frame=''>-0.315871 0.016 -0.013949 -0.604825 -0.143825 0.148221</pose>
        <inertial>
          <pose frame=''>0.0975 0 -0 0 -0 0</pose>
          <mass>0.0200332</mass>
          <inertia>
		  <ixx>0</ixx> <ixy>0</ixy> <ixz>0</ixz>
		  <iyy>0</iyy> <iyz>0</iyz> <izz>0</izz>
          </inertia>
        </inertial>
        <visual name='bli_visual'>
          <pose frame=''>0 0 0 0 -0 0</pose>
          <geometry>
            <mesh>
              <scale>1 1 1</scale>
              <uri>model://meshes/linkageIn.STL</uri>
            </mesh>
          </geometry>
        </visual>
      </link>
      <link name='blo'>
        <pose frame=''>-0.322508 0.07075 -0.085227 2.55732 -0.269455 -0.041735</pose>
        <inertial>
          <pose frame=''>0.115 0 0 0 -0 0</pose>
          <mass>0.0117925</mass>
          <inertia>
		  <ixx>0</ixx> <ixy>0</ixy> <ixz>0</ixz>
		  <iyy>0</iyy> <iyz>0</iyz> <izz>0</izz>
          </inertia>
        </inertial>
        <visual name='blo_visual'>
          <pose frame=''>0 0 0 0 -0 0</pose>
          <geometry>
            <mesh>
              <scale>1 1 1</scale>
              <uri>model://meshes/linkageOut.STL</uri>
            </mesh>
          </geometry>
        </visual>
      </link>
      <link name='blslower'>
        <pose frame=''>-0.318186 0.092 -0.068785 -0.568218 -0.618473 -0.161762</pose>
        <inertial>
          <pose frame=''>0.016589 -0 0 0 -0 0</pose>
          <mass>0.0112311</mass>
          <inertia>
		  <ixx>0</ixx> <ixy>0</ixy> <ixz>0</ixz>
		  <iyy>0</iyy> <iyz>0</iyz> <izz>0</izz>
          </inertia>
        </inertial>
        <visual name='blslower_visual'>
          <pose frame=''>0 0 0 0 -0 0</pose>
          <geometry>
            <mesh>
              <scale>1 1 1</scale>
              <uri>model://meshes/springPart.STL</uri>
            </mesh>
          </geometry>
        </visual>
      </link>
      <link name='blsupper'>
        <pose frame=''>-0.1895 0.071 0.024 2.41118 0.618473 2.97983</pose>
        <inertial>
          <pose frame=''>0.016589 -0 0 0 -0 0</pose>
          <mass>0.0112311</mass>
          <inertia>
		  <ixx>0</ixx> <ixy>0</ixy> <ixz>0</ixz>
		  <iyy>0</iyy> <iyz>0</iyz> <izz>0</izz>
          </inertia>
        </inertial>
        <visual name='blsupper_visual'>
          <pose frame=''>0 0 0 0 -0 0</pose>
          <geometry>
            <mesh>
              <scale>1 1 1</scale>
              <uri>model://meshes/springPart.STL</uri>
            </mesh>
          </geometry>
        </visual>
      </link>
      <link name='blwheel'>
        <pose frame=''>-0.342683 0.115 -0.074 -2.8743 -0 1.5708</pose>
        <inertial>
          <pose frame=''>0.00750009171 0 0 0 -0 0</pose>
          <mass>0.19539</mass>
          <inertia>
		  <ixx>0</ixx> <ixy>0</ixy> <ixz>0</ixz>
		  <iyy>0</iyy> <iyz>0</iyz> <izz>0</izz>
          </inertia>
        </inertial>
        <visual name='blwheel_visual'>
          <pose frame=''>0 0 0 0 -0 0</pose>
          <geometry>
            <mesh>
              <scale>1 1 1</scale>
              <uri>model://meshes/wheelHub.STL</uri>
            </mesh>
          </geometry>
        </visual>
      </link>
      <link name='bri'>
        <pose frame=''>-0.315871 -0.016 -0.013949 1.44194 -0.143825 -0.148221</pose>
        <inertial>
          <pose frame=''>0.0975 0 0 0 -0 0</pose>
          <mass>0.0200332</mass>
          <inertia>
		  <ixx>0</ixx> <ixy>0</ixy> <ixz>0</ixz>
		  <iyy>0</iyy> <iyz>0</iyz> <izz>0</izz>
          </inertia>
        </inertial>
        <visual name='bri_visual'>
          <pose frame=''>0 0 0 0 -0 0</pose>
          <geometry>
            <mesh>
              <scale>1 1 1</scale>
              <uri>model://meshes/linkageIn.STL</uri>
            </mesh>
          </geometry>
        </visual>
      </link>
      <link name='brslower'>
        <pose frame=''>-0.318186 -0.092 -0.068785 -0.210766 -0.618473 0.161762</pose>
        <inertial>
          <pose frame=''>0.016589 0 0 0 -0 0</pose>
          <mass>0.0112311</mass>
          <inertia>
		  <ixx>0</ixx> <ixy>0</ixy> <ixz>0</ixz>
		  <iyy>0</iyy> <iyz>0</iyz> <izz>0</izz>
          </inertia>
        </inertial>
        <visual name='brslower_visual'>
          <pose frame=''>0 0 0 0 -0 0</pose>
          <geometry>
            <mesh>
              <scale>1 1 1</scale>
              <uri>model://meshes/springPart.STL</uri>
            </mesh>
          </geometry>
        </visual>
      </link>
      <link name='brsupper'>
        <pose frame=''>-0.1895 -0.071 0.024 2.05373 0.618473 -2.97983</pose>
        <inertial>
          <pose frame=''>0.016589 -0 0 0 -0 0</pose>
          <mass>0.0112311</mass>
          <inertia>
		  <ixx>0</ixx> <ixy>0</ixy> <ixz>0</ixz>
		  <iyy>0</iyy> <iyz>0</iyz> <izz>0</izz>
          </inertia>
        </inertial>
        <visual name='brsupper_visual'>
          <pose frame=''>0 0 0 0 -0 0</pose>
          <geometry>
            <mesh>
              <scale>1 1 1</scale>
              <uri>model://meshes/springPart.STL</uri>
            </mesh>
          </geometry>
        </visual>
      </link>
      <link name='brwheel'>
        <pose frame=''>-0.342683 -0.115 -0.074 2.8743 0 -1.5708</pose>
        <inertial>
          <pose frame=''>0.00750009171 -0 0 0 -0 0</pose>
          <mass>0.19539</mass>
          <inertia>
		  <ixx>0</ixx> <ixy>0</ixy> <ixz>0</ixz>
		  <iyy>0</iyy> <iyz>0</iyz> <izz>0</izz>
          </inertia>
        </inertial>
        <visual name='brwheel_visual'>
          <pose frame=''>0 0 0 0 -0 0</pose>
          <geometry>
            <mesh>
              <scale>1 1 1</scale>
              <uri>model://meshes/wheelHub.STL</uri>
            </mesh>
          </geometry>
        </visual>
      </link>
      <link name='bltire'>
        <pose frame=''>-0.342683 0.135 -0.074 -2.31924 -0 1.5708</pose>
        <inertial>
          <pose frame=''>0.045 0 -0 0 -0 0</pose>
          <mass>2.65072</mass>
          <inertia>
		  <ixx>0</ixx> <ixy>0</ixy> <ixz>0</ixz>
		  <iyy>0</iyy> <iyz>0</iyz> <izz>0</izz>
          </inertia>
        </inertial>
        <collision name='bltire_collision'>
          <pose frame=''>0.045 0 0 0 1.57079632679 0</pose>
          <geometry>
            <cylinder>
              <radius>0.1 0 0</radius>
              <length>0.09 0 0</length>
            </cylinder>
          </geometry>
        </collision>
        <visual name='bltire_visual'>
          <pose frame=''>0.045 0 0 0 1.57079632679 0</pose>
          <geometry>
            <cylinder>
              <radius>0.1 0 0</radius>
              <length>0.09 0 0</length>
            </cylinder>
          </geometry>
        </visual>
      </link>
      <link name='brtire'>
        <pose frame=''>-0.342683 -0.225 -0.074 -2.87457 -0 1.5708</pose>
        <inertial>
          <pose frame=''>0.045 0 0 0 -0 0</pose>
          <mass>2.65072</mass>
          <inertia>
		  <ixx>0</ixx> <ixy>0</ixy> <ixz>0</ixz>
		  <iyy>0</iyy> <iyz>0</iyz> <izz>0</izz>
          </inertia>
        </inertial>
        <collision name='brtire_collision'>
          <pose frame=''>0.045 0 0 0 1.57079632679 0</pose>
          <geometry>
            <cylinder>
              <radius>0.1 0 0</radius>
              <length>0.09 0 0</length>
            </cylinder>
          </geometry>
        </collision>
        <visual name='brtire_visual'>
          <pose frame=''>0.045 0 0 0 1.57079632679 0</pose>
          <geometry>
            <cylinder>
              <radius>0.1 0 0</radius>
              <length>0.09 0 0</length>
            </cylinder>
          </geometry>
        </visual>
      </link>
      <link name='fro'>
        <pose frame=''>0.101 -0.0615 -0.024 2.1962 0.26945 -0.041735</pose>
        <inertial>
          <pose frame=''>0.115 -0 0 0 -0 0</pose>
          <mass>0.0117925</mass>
          <inertia>
		  <ixx>0</ixx> <ixy>0</ixy> <ixz>0</ixz>
		  <iyy>0</iyy> <iyz>0</iyz> <izz>0</izz>
          </inertia>
        </inertial>
        <visual name='fro_visual'>
          <pose frame=''>0 0 0 0 -0 0</pose>
          <geometry>
            <mesh>
              <scale>1 1 1</scale>
              <uri>model://meshes/linkageOut.STL</uri>
            </mesh>
          </geometry>
        </visual>
      </link>
      <link name='frontAxle'>
        <pose frame=''>0.322508 -0.07075 -0.085226 -0.267269 -2.4e-05 1.57078</pose>
        <inertial>
          <pose frame=''>0.07075 -0.019868 0.013586 0 -0 0</pose>
          <mass>0.0969889</mass>
          <inertia>
		  <ixx>0</ixx> <ixy>0</ixy> <ixz>0</ixz>
		  <iyy>0</iyy> <iyz>0</iyz> <izz>0</izz>
          </inertia>
        </inertial>
        <visual name='frontAxle_visual'>
          <pose frame=''>0 0 0 0 -0 0</pose>
          <geometry>
            <mesh>
              <scale>1 1 1</scale>
              <uri>model://meshes/axleFront.STL</uri>
            </mesh>
          </geometry>
        </visual>
        <collision name='frontAxle_collision'>
          <pose frame=''>0 0 0 0 -0 0</pose>
          <geometry>
            <mesh>
              <scale>1 1 1</scale>
              <uri>model://meshes/axleFront.STL</uri>
            </mesh>
          </geometry>
        </collision>
      </link>
      <link name='fli'>
        <pose frame=''>0.315873 0.015998 -0.013946 0.904649 -0.143848 2.99336</pose>
        <inertial>
          <pose frame=''>0.0975 0 -0 0 -0 0</pose>
          <mass>0.0200332</mass>
          <inertia>
		  <ixx>0</ixx> <ixy>0</ixy> <ixz>0</ixz>
		  <iyy>0</iyy> <iyz>0</iyz> <izz>0</izz>
          </inertia>
        </inertial>
        <visual name='fli_visual'>
          <pose frame=''>0 0 0 0 -0 0</pose>
          <geometry>
            <mesh>
              <scale>1 1 1</scale>
              <uri>model://meshes/linkageIn.STL</uri>
            </mesh>
          </geometry>
        </visual>
      </link>
      <link name='flo'>
        <pose frame=''>0.32251 0.07075 -0.085223 0.756048 -0.269473 -3.09986</pose>
        <inertial>
          <pose frame=''>0.115 -0 -0 0 -0 0</pose>
          <mass>0.0117925</mass>
          <inertia>
		  <ixx>0</ixx> <ixy>0</ixy> <ixz>0</ixz>
		  <iyy>0</iyy> <iyz>0</iyz> <izz>0</izz>
          </inertia>
        </inertial>
        <visual name='flo_visual'>
          <pose frame=''>0 0 0 0 -0 0</pose>
          <geometry>
            <mesh>
              <scale>1 1 1</scale>
              <uri>model://meshes/linkageOut.STL</uri>
            </mesh>
          </geometry>
        </visual>
      </link>
      <link name='flslower'>
        <pose frame=''>0.318189 0.092 -0.06878 -1.43248 -0.618488 -2.97982</pose>
        <inertial>
          <pose frame=''>0.016589 -0 0 0 -0 0</pose>
          <mass>0.0112311</mass>
          <inertia>
		  <ixx>0</ixx> <ixy>0</ixy> <ixz>0</ixz>
		  <iyy>0</iyy> <iyz>0</iyz> <izz>0</izz>
          </inertia>
        </inertial>
        <visual name='flslower_visual'>
          <pose frame=''>0 0 0 0 -0 0</pose>
          <geometry>
            <mesh>
              <scale>1 1 1</scale>
              <uri>model://meshes/springPart.STL</uri>
            </mesh>
          </geometry>
        </visual>
      </link>
      <link name='flsupper'>
        <pose frame=''>0.189504 0.070999 0.024007 2.4484 0.618488 0.161768</pose>
        <inertial>
          <pose frame=''>0.016589 -0 0 0 -0 0</pose>
          <mass>0.0112311</mass>
          <inertia>
		  <ixx>0</ixx> <ixy>0</ixy> <ixz>0</ixz>
		  <iyy>0</iyy> <iyz>0</iyz> <izz>0</izz>
          </inertia>
        </inertial>
        <visual name='flsupper_visual'>
          <pose frame=''>0 0 0 0 -0 0</pose>
          <geometry>
            <mesh>
              <scale>1 1 1</scale>
              <uri>model://meshes/springPart.STL</uri>
            </mesh>
          </geometry>
        </visual>
      </link>
      <link name='flwheel'>
        <pose frame=''>0.342686 0.114999 -0.073995 2.87432 -2.4e-05 1.57078</pose>
        <inertial>
          <pose frame=''>0.00750009171 0 0 0 -0 0</pose>
          <mass>0.19539</mass>
          <inertia>
		  <ixx>0</ixx> <ixy>0</ixy> <ixz>0</ixz>
		  <iyy>0</iyy> <iyz>0</iyz> <izz>0</izz>
          </inertia>
        </inertial>
        <visual name='flwheel_visual'>
          <pose frame=''>0 0 0 0 -0 0</pose>
          <geometry>
            <mesh>
              <scale>1 1 1</scale>
              <uri>model://meshes/wheelHub.STL</uri>
            </mesh>
          </geometry>
        </visual>
      </link>
      <link name='fri'>
        <pose frame=''>0.315873 -0.016002 -0.013947 0.861564 -0.143841 -2.99338</pose>
        <inertial>
          <pose frame=''>0.0975 0 -0 0 -0 0</pose>
          <mass>0.0200332</mass>
          <inertia>
		  <ixx>0</ixx> <ixy>0</ixy> <ixz>0</ixz>
		  <iyy>0</iyy> <iyz>0</iyz> <izz>0</izz>
          </inertia>
        </inertial>
        <visual name='fri_visual'>
          <pose frame=''>0 0 0 0 -0 0</pose>
          <geometry>
            <mesh>
              <scale>1 1 1</scale>
              <uri>model://meshes/linkageIn.STL</uri>
            </mesh>
          </geometry>
        </visual>
      </link>
      <link name='frslower'>
        <pose frame=''>0.318186 -0.092 -0.068784 -0.708805 -0.618496 2.97983</pose>
        <inertial>
          <pose frame=''>0.016589 -0 0 0 -0 0</pose>
          <mass>0.0112311</mass>
          <inertia>
		  <ixx>0</ixx> <ixy>0</ixy> <ixz>0</ixz>
		  <iyy>0</iyy> <iyz>0</iyz> <izz>0</izz>
          </inertia>
        </inertial>
        <visual name='frslower_visual'>
          <pose frame=''>0 0 0 0 -0 0</pose>
          <geometry>
            <mesh>
              <scale>1 1 1</scale>
              <uri>model://meshes/springPart.STL</uri>
            </mesh>
          </geometry>
        </visual>
      </link>
      <link name='frsupper'>
        <pose frame=''>0.189502 -0.071001 0.024004 1.72472 0.618496 -0.161761</pose>
        <inertial>
          <pose frame=''>0.016589 -0 0 0 -0 0</pose>
          <mass>0.0112311</mass>
          <inertia>
		  <ixx>0</ixx> <ixy>0</ixy> <ixz>0</ixz>
		  <iyy>0</iyy> <iyz>0</iyz> <izz>0</izz>
          </inertia>
        </inertial>
        <visual name='frsupper_visual'>
          <pose frame=''>0 0 0 0 -0 0</pose>
          <geometry>
            <mesh>
              <scale>1 1 1</scale>
              <uri>model://meshes/springPart.STL</uri>
            </mesh>
          </geometry>
        </visual>
      </link>
      <link name='frwheel'>
        <pose frame=''>0.342683 -0.115001 -0.074 0.267269 2.4e-05 -1.57081</pose>
        <inertial>
          <pose frame=''>0.00750009171 0 -0 0 -0 0</pose>
          <mass>0.19539</mass>
          <inertia>
		  <ixx>0</ixx> <ixy>0</ixy> <ixz>0</ixz>
		  <iyy>0</iyy> <iyz>0</iyz> <izz>0</izz>
          </inertia>
        </inertial>
        <visual name='frwheel_visual'>
          <pose frame=''>0 0 0 0 -0 0</pose>
          <geometry>
            <mesh>
              <scale>1 1 1</scale>
              <uri>model://meshes/wheelHub.STL</uri>
            </mesh>
          </geometry>
        </visual>
      </link>
      <link name='fltire'>
        <pose frame=''>0.342686 0.134999 -0.073994 -1.4358 -2.4e-05 1.57078</pose>
        <inertial>
          <pose frame=''>0.045 0 0 0 -0 0</pose>
          <mass>2.65072</mass>
          <inertia>
		  <ixx>0</ixx> <ixy>0</ixy> <ixz>0</ixz>
		  <iyy>0</iyy> <iyz>0</iyz> <izz>0</izz>
          </inertia>
        </inertial>
        <collision name='fltire_collision'>
          <pose frame=''>0.045 0 0 0 1.57079632679 0</pose>
          <geometry>
            <cylinder>
              <radius>0.1 0 0</radius>
              <length>0.09 0 0</length>
            </cylinder>
          </geometry>
        </collision>
        <visual name='fltire_visual'>
          <pose frame=''>0.045 0 0 0 1.57079632679 0</pose>
          <geometry>
            <cylinder>
              <radius>0.1 0 0</radius>
              <length>0.09 0 0</length>
            </cylinder>
          </geometry>
        </visual>
      </link>
      <link name='frtire'>
        <pose frame=''>0.342682 -0.225001 -0.074003 -1.07467 -2.4e-05 1.57078</pose>
        <inertial>
          <pose frame=''>0.045 -0 0 0 -0 0</pose>
          <mass>2.65072</mass>
          <inertia>
		  <ixx>0</ixx> <ixy>0</ixy> <ixz>0</ixz>
		  <iyy>0</iyy> <iyz>0</iyz> <izz>0</izz>
          </inertia>
        </inertial>
        <collision name='frtire_collision'>
          <pose frame=''>0.045 0 0 0 1.57079632679 0</pose>
          <geometry>
            <cylinder>
              <radius>0.1 0 0</radius>
              <length>0.09 0 0</length>
            </cylinder>
          </geometry>
        </collision>
        <visual name='frtire_visual'>
          <pose frame=''>0.045 0 0 0 1.57079632679 0</pose>
          <geometry>
            <cylinder>
              <radius>0.1 0 0</radius>
              <length>0.09 0 0</length>
            </cylinder>
          </geometry>
        </visual>
      </link>-->

      <!-- Joints-->
      <joint name='body2bro' type='spherical'>
        <child>bro</child>
        <parent>body</parent>
        <axis>
          <xyz>1 0 0</xyz>
        </axis>
      </joint>
      <joint name='bro2axle' type='spherical'>
        <child>backAxle</child>
        <parent>bro</parent>
        <axis>
          <xyz>1 0 0</xyz>
        </axis>
      </joint>
      <joint name='axle2bli' type='spherical'>
        <child>bli</child>
        <parent>backAxle</parent>
        <axis>
          <xyz>1 0 0</xyz>
        </axis>
      </joint>

      <joint name='axle2blo' type='spherical'>
        <child>blo</child>
        <parent>backAxle</parent>
        <axis>
          <xyz>1 0 0</xyz>
        </axis>
      </joint>
      <joint name='axle2blslower' type='spherical'>
        <child>blslower</child>
        <parent>backAxle</parent>
        <axis>
          <xyz>1 0 0</xyz>
        </axis>
      </joint>
      <joint name='axle2blwheel' type='continuous'>
        <child>blwheel</child>
        <parent>backAxle</parent>
        <axis>
          <xyz>0.264117 0 0.964491</xyz>
          <use_parent_model_frame>1</use_parent_model_frame>
        </axis>
      </joint>
      <joint name='blwheel2tire' type='continuous'>
        <child>bltire</child>
        <parent>blwheel</parent>
        <axis>
          <xyz>1 0 0</xyz>
        </axis>
      </joint>
      <joint name='axle2bri' type='spherical'>
        <child>bri</child>
        <parent>backAxle</parent>
        <axis>
          <xyz>1 0 0</xyz>
        </axis>
      </joint>
      <joint name='axle2brslower' type='spherical'>
        <child>brslower</child>
        <parent>backAxle</parent>
        <axis>
          <xyz>1 0 0</xyz>
        </axis>
      </joint>
      <joint name='axle2brwheel' type='continuous'>
        <child>brwheel</child>
        <parent>backAxle</parent>
        <axis>
          <xyz>0.264117 0 0.964491</xyz>
          <use_parent_model_frame>1</use_parent_model_frame>
        </axis>
      </joint>
      <joint name='brwheel2tire' type='continuous'>
        <child>brtire</child>
        <parent>brwheel</parent>
        <axis>
          <xyz>1 0 0</xyz>
        </axis>
      </joint>
      <joint name='body2fro' type='spherical'>
        <child>fro</child>
        <parent>body</parent>
        <axis>
          <xyz>1 0 0</xyz>
        </axis>
      </joint>
      <joint name='fro2Axle' type='spherical'>
        <child>frontAxle</child>
        <parent>fro</parent>
        <axis>
          <xyz>1 0 0</xyz>
        </axis>
      </joint>
      <joint name='axle2fli' type='spherical'>
        <child>fli</child>
        <parent>frontAxle</parent>
        <axis>
          <xyz>1 0 0</xyz>
        </axis>
      </joint>
      <joint name='axle2flo' type='spherical'>
        <child>flo</child>
        <parent>frontAxle</parent>
        <axis>
          <xyz>1 0 0</xyz>
        </axis>
      </joint>
      <joint name='axle2flslower' type='spherical'>
        <child>flslower</child>
        <parent>frontAxle</parent>
        <axis>
          <xyz>1 0 0</xyz>
        </axis>
      </joint>
      <joint name='axle2flwheel' type='continuous'>
        <child>flwheel</child>
        <parent>frontAxle</parent>
        <axis>
          <xyz>-0.264098 -2e-05 0.964496</xyz>
          <use_parent_model_frame>1</use_parent_model_frame>
        </axis>
      </joint>
      <joint name='flwheel2tire' type='continuous'>
        <child>fltire</child>
        <parent>flwheel</parent>
        <axis>
          <xyz>1 0 0</xyz>
        </axis>
      </joint>
      <joint name='axle2fri' type='spherical'>
        <child>fri</child>
        <parent>frontAxle</parent>
        <axis>
          <xyz>1 0 0</xyz>
        </axis>
      </joint>
      <joint name='axle2frslower' type='spherical'>
        <child>frslower</child>
        <parent>frontAxle</parent>
        <axis>
          <xyz>1 0 0</xyz>
        </axis>
      </joint>
      <joint name='axle2frwheel' type='continuous'>
        <child>frwheel</child>
        <parent>frontAxle</parent>
        <axis>
          <xyz>0.264098 2e-05 -0.964496</xyz>
          <use_parent_model_frame>1</use_parent_model_frame>
        </axis>
      </joint>
      <joint name='frwheel2tire' type='continuous'>
        <child>frtire</child>
        <parent>frwheel</parent>
        <axis>
          <xyz>1 0 0</xyz>
        </axis>
      </joint>

      <!-- Suspension Componenets -->
      <joint name='brslower2upper' type='prismatic'>
        <child>brsupper</child>
        <parent>brslower</parent>
        <axis>
          <xyz>1 0 0</xyz>
          <limit>
            <lower>-1e+15</lower>
            <upper>1e+15</upper>
          </limit>
        </axis>
      </joint>
      <joint name='blslower2upper' type='prismatic'>
        <child>blsupper</child>
        <parent>blslower</parent>
        <axis>
          <xyz>1 0 0</xyz>
          <limit>
            <lower>-1e+15</lower>
            <upper>1e+15</upper>
          </limit>
        </axis>
      </joint>
      <joint name='frslower2upper' type='prismatic'>
        <child>frsupper</child>
        <parent>frslower</parent>
        <axis>
          <xyz>1 0 0</xyz>
          <limit>
            <lower>-1e+15</lower>
            <upper>1e+15</upper>
          </limit>
        </axis>
      </joint>
      <joint name='flslower2upper' type='prismatic'>
        <child>flsupper</child>
        <parent>flslower</parent>
        <axis>
          <xyz>1 0 0</xyz>
          <limit>
            <lower>-1e+15</lower>
            <upper>1e+15</upper>
          </limit>
        </axis>
      </joint>
    </model>
  </world>

</sdf>
